Workbook

Sheet Capa
B2: ANÁLISE FORENSE — SAF BOTAFOGO
B3: 2º post da série RJ — Substack Vinicius Borges
B4: Data de fechamento: 13/05/2026
B6: TESE CENTRAL
B7: A SAF Botafogo 2022-2024 foi sustentada por 5 pilares paralelos do controlador totalizando R$ 1,2 BI em 2024. Em 2025, todos os pilares zeraram/colapsaram simultaneamente. EBITDA recorrente puro nunca foi positivo em 4 anos. RJ protocolada 22/04/2026; disclaimer of opinion BDO 08/05/2026; cross-claim Lyon R$ 727 MM publicado 12/05/2026.
B9: FONTES PRIMÁRIAS
B10: Balanço auditado 2024 (reapresentado em 2025) | C10: BDO RCS, parecer 10/06/2025, going concern qualified
B11: Balanço auditado 2025 | C11: BDO RCS, parecer 08/05/2026, ABSTENÇÃO DE OPINIÃO (7 bases)
B12: Reapresentações 2023 | C12: Notas 3.1/3.2 do balanço auditado 2024 (ITG 2003 R2)
B13: Reapresentação 2024 | C13: Nota 3.1 do balanço auditado 2025
B15: FONTES SECUNDÁRIAS
B16: Balanço OL SASU 2025 | C16: Publicado 12/05/2026, contraclaim R$ 727 MM contra Botafogo
B17: Tribunal Arbitral FGV | C17: Afastamento Textor 23/04/2026; devolução direitos políticos Eagle 11/05/2026
B18: TJ-RJ 2ª Vara Empresarial | C18: Suspensão decisão arbitral 12/05/2026
B19: Petição inicial RJ | C19: Protocolo 22/04/2026 — Lei 11.101/2005 + 14.193/2021
B21: CONVENÇÕES VISUAIS
B22: Azul | C22: Input hardcoded (vem da fonte primária)
B23: Preto | C23: Fórmula (calculado a partir de inputs)
B24: Verde | C24: Link entre abas dentro da planilha
B25: Amarelo (fundo) | C25: Premissa-chave editável que pode mudar com novas evidências
B26: Cinza (fundo) | C26: Subtotais e totais
B28: UNIDADES E CÂMBIO
B29: Valores monetários | C29: R$ mil (milhares de reais), exceto onde indicado
B30: Câmbio referência | C30: R$ 5,80 / EUR (premissa, ajustável em Premissas Runway)
B32: NOTAS METODOLÓGICAS
B33: • Reapresentação ITG 2003 R2: vendas de atletas em linha separada (Receitas com transações de direitos de atletas).
B34: • EBITDA recorrente puro = Resultado operacional antes da alienação + D&A pura − não-recorrentes (LFU 20% em 2023; recuperação de gastos em 2025).
B35: • Folha ampliada = salários + encargos + benefícios + direitos de imagem (custos + DGA), sem amortização de atletas.
B36: • 4 condições de competitividade (critérios rigorosos): folha ≤ 65% RL; EBITDA ≥ +5% margem; capex atletas ≤ receita cessão; caixa ≥ 1 mês de saídas.
B37: • 3 cenários de runway (Otimista, Base, Pessimista) × 2 anos (2026-2027). Aporte de capital novo = R$ 0 em TODOS os cenários (premissa firme).
B38: • Disputa política Textor/Eagle/Lyon FORA do escopo editorial. Impactos financeiros mensuráveis incluídos, teatro político omitido.
B39: • Validação: Total Ativo = Total Passivo + PL nos 3 anos (ver indicador de check no rodapé do BP).
B41: ESTRUTURA DESTA PLANILHA
B42: 1. BP | C42: 3 anos lado a lado (2023r, 2024r, 2025); validação A = P + PL
B43: 2. DRE | C43: 3 anos com margens; estrutura ITG 2003 R2
B44: 3. Receita Detalhada | C44: Decomposição: recorrente vs premiações vs bilheteria vs cessão
B45: 4. DFC | C45: 3 anos, método indireto
B46: 5. Operacional Puro | C46: EBITDA recorrente puro 2022-2025: reconciliação reportado → puro
B47: 6. Indicadores | C47: Síntese: liquidez, endividamento, operacional, folha
B48: 7. Premissas Runway | C48: Premissas editáveis dos 3 cenários × 2 anos
...

Sheet BP
A1: BALANÇO PATRIMONIAL — CONTROLADORA (R$ mil)
A2: Linha | B2: 2023 reapres | C2: 2024 reapres | D2: 2025 | E2: Δ 2025 vs 2024r | F2: Δ % 2025 vs 2024r
A4: ATIVO
A5: Ativo Circulante
A6: Caixa e equivalentes de caixa | B6: 16057 | C6: 128951 | D6: 25557
A7: Contas a receber | B7: 82645 | C7: 114907 | D7: 56066
A8: Estoque | B8: 7016 | C8: 5293 | D8: 21915
A9: Partes relacionadas | B9: 369606 | C9: 402125 | D9: 279519
A10: Adiantamentos | B10: 1488 | C10: 2544 | D10: 1597
A11: Impostos a recuperar | B11: 203 | C11: 426 | D11: 414
A12: Despesas antecipadas | B12: 3654 | C12: 6638 | D12: 16495
A13: Total Ativo Circulante | B13: =SUM(B6:B12) -> 480669 | C13: =SUM(C6:C12) -> 660884 | D13: =SUM(D6:D12) -> 401563
A14: Ativo Não-Circulante
A15: Contas a receber (LP) | B15: 31835 | C15: 5837 | D15: 15734
A16: Partes relacionadas (LP) | B16: 130188 | C16: 189742 | D16: 285164
A17: Outros ativos | B17: 2015 | C17: 129 | D17: 5227
A18: Investimento (sub) | B18: 0 | C18: 15439 | D18: 8895
A19: Ativo de Direito de Uso | B19: 8313 | C19: 16843 | D19: 13750
A20: Imobilizado | B20: 11025 | C20: 14244 | D20: 39862
A21: Intangível | B21: 157543 | C21: 521602 | D21: 814239
A22: Total Ativo Não-Circulante | B22: =SUM(B15:B21) -> 340919 | C22: =SUM(C15:C21) -> 763836 | D22: =SUM(D15:D21) -> 1182871
A23: TOTAL DO ATIVO | B23: =B13+B22 -> 821588 | C23: =C13+C22 -> 1424720 | D23: =D13+D22 -> 1584434
A25: PASSIVO
A26: Passivo Circulante
A27: Fornecedores e contas a pagar | B27: 153603 | C27: 479803 | D27: 880769
A28: Empréstimos e financiamentos | B28: 377592 | C28: 48112 | D28: 88324
A29: Obrigações trabalhistas | B29: 24682 | C29: 78211 | D29: 31949
A30: Obrigações tributárias | B30: 51380 | C30: 97594 | D30: 199688
A31: Partes relacionadas passivo | B31: 36198 | C31: 80184 | D31: 5970
A32: Passivo de arrendamento | B32: 2107 | C32: 4089 | D32: 5216
A33: Receita diferida | B33: 51090 | C33: 421939 | D33: 140829
A34: Adiantamento de clientes | B34: 0 | C34: 0 | D34: 850
A35: Total Passivo Circulante | B35: =SUM(B27:B34) -> 696652 | C35: =SUM(C27:C34) -> 1209932 | D35: =SUM(D27:D34) -> 1353595
A36: Passivo Não-Circulante
A37: Fornecedores e contas a pagar (LP) | B37: 21613 | C37: 168164 | D37: 286800
A38: Empréstimos e financiamentos (LP) | B38: 0 | C38: 0 | D38: 50648
A39: Obrigações tributárias (LP) | B39: 95687 | C39: 154438 | D39: 201118
A40: Provisão para contingências | B40: 4251 | C40: 18340 | D40: 26741
A41: Passivo de arrendamento (LP) | B41: 7186 | C41: 14864 | D41: 11258
A42: Receita diferida (LP) | B42: 25000 | C42: 0 | D42: 86191
...

Sheet DRE
A1: DEMONSTRAÇÃO DO RESULTADO — CONTROLADORA (R$ mil)
A2: Linha | B2: 2023 reapres | C2: 2024 reapres | D2: 2025 | E2: Δ 2025 vs 2024r
A4: Receita Operacional Bruta | B4: 312042 | C4: 607322 | D4: 655033 | E4: =D4-C4 -> 47711
A5: Deduções sobre a receita | B5: -32845 | C5: -55051 | D5: -81027 | E5: =D5-C5 -> -25976
A6: Receita Operacional, líquida | B6: =B4+B5 -> 279197 | C6: =C4+C5 -> 552271 | D6: =D4+D5 -> 574006 | E6: =D6-C6 -> 21735
A7: Custo dos serviços prestados | B7: -374834 | C7: -608584 | D7: -675254 | E7: =D7-C7 -> -66670
A8: Resultado Bruto | B8: =B6+B7 -> -95637 | C8: =C6+C7 -> -56313 | D8: =D6+D7 -> -101248 | E8: =D8-C8 -> -44935
A9: Despesas gerais e administrativas | B9: -104410 | C9: -145897 | D9: -218212 | E9: =D9-C9 -> -72315
A10: Outras despesas operacionais | B10: -310 | C10: -623 | D10: -498 | E10: =D10-C10 -> 125
A11: Outras receitas operacionais | B11: 182048 | C11: 49223 | D11: 52436 | E11: =D11-C11 -> 3213
A12: Resultado de equivalência patrimonial | B12: 0 | C12: -6509 | D12: -6544 | E12: =D12-C12 -> -35
A13: Resultado Operacional Antes da Alienação de Ativos | B13: =B8+B9+B10+B11+B12 -> -18309 | C13: =C8+C9+C10+C11+C12 -> -160119 | D13: =D8+D9+D10+D11+D12 -> -274066 | E13: =D13-C13 -> -113947
A14: Receitas com transações de direitos de atletas | B14: 77000 | C14: 96356 | D14: 733361 | E14: =D14-C14 -> 637005
A15: Gastos na transação de direitos de atletas | B15: -37222 | C15: -45832 | D15: -448843 | E15: =D15-C15 -> -403011
A16: Resultado Operacional Total (após cessão atletas) | B16: =B13+B14+B15 -> 21469 | C16: =C13+C14+C15 -> -109595 | D16: =D13+D14+D15 -> 10452 | E16: =D16-C16 -> 120047
A17: Resultado financeiro líquido | B17: -77506 | C17: -157222 | D17: -301350 | E17: =D17-C17 -> -144128
A18: PREJUÍZO DO EXERCÍCIO | B18: =B16+B17 -> -56037 | C18: =C16+C17 -> -266817 | D18: =D16+D17 -> -290898 | E18: =D18-C18 -> -24081
A20: INDICADORES DERIVADOS
A21: Margem bruta | B21: =IFERROR(B8/B6,"-") -> -0.34254308 | C21: =IFERROR(C8/C6,"-") -> -0.10196624 | D21: =IFERROR(D8/D6,"-") -> -0.1763884
A22: Margem operacional pré-alienação | B22: =IFERROR(B13/B6,"-") -> -0.065577352 | C22: =IFERROR(C13/C6,"-") -> -0.28992831 | D22: =IFERROR(D13/D6,"-") -> -0.47746191
A23: Margem líquida | B23: =IFERROR(B18/B6,"-") -> -0.20070774 | C23: =IFERROR(C18/C6,"-") -> -0.48312694 | D23: =IFERROR(D18/D6,"-") -> -0.50678564
A24: Crescimento receita líquida YoY | C24: =IFERROR(C6/B6-1,"-") -> 0.97806925 | D24: =IFERROR(D6/C6-1,"-") -> 0.039355679
A25: Resultado líquido cessão atletas | B25: =B14+B15 -> 39778 | C25: =C14+C15 -> 50524 | D25: =D14+D15 -> 284518
A27: Notas:
A28: (1) 2023 reapres: estrutura ITG 2003 R2. Linha "Outras receitas operacionais" inclui R$ 165 MM da venda LFU 20% (não-recorrente — ajustado em Operacional Puro).
A29: (2) Reapresentação 2024: ajuste de +R$ 33 MM em "Outras receitas operacionais" reduziu o prejuízo de R$ 300 MM para R$ 267 MM.
A30: (3) Em 2025, receita cessão atletas (R$ 733 MM) é 8x maior que 2024. Sem essa linha, prejuízo seria ~R$ 575 MM (vs R$ 290 MM efetivo).
A31: (4) Receita líquida cresceu apenas 4% em 2025, abaixo da inflação, mesmo com Mundial de Clubes (R$ 148 MM).

Sheet Receita Detalhada
A1: RECEITA DETALHADA — DECOMPOSIÇÃO POR CATEGORIA (R$ mil)
A2: Linha | B2: 2022 | C2: 2023 | D2: 2024 | E2: 2025 | F2: Δ 2025 vs 2024
A4: RECORRENTE (BASE ESTRUTURAL)
A5: Direitos transmissão — Brasileirão | D5: 84982 | E5: 93175 | F5: =E5-D5 -> 8193
A6: Direitos transmissão — Carioca | D6: 16000 | E6: 18000 | F6: =E6-D6 -> 2000
A7: Patrocínio Master | B7: 16000 | C7: 42000 | D7: 37500 | E7: 55000 | F7: =E7-D7 -> 17500
A8: Outros Patrocínios + Publicidade + Digital | D8: 18411 | E8: 37190 | F8: =E8-D8 -> 18779
A9: Camisa 7 (sócio torcedor) | B9: 8000 | C9: 28000 | D9: 48620 | E9: 52013 | F9: =E9-D9 -> 3393
A10: Camisa 6 (sócio CT) | B10: 0 | C10: 0 | D10: 0 | E10: 460
A11: Licenciamento | D11: 3177 | E11: 3500 | F11: =E11-D11 -> 323
A12: Botafogo Store (mercadorias) | B12: 2000 | C12: 24000 | D12: 66379 | E12: 60646 | F12: =E12-D12 -> -5733
A13: Locações estádio + camarotes | D13: 24233 | E13: 23773 | F13: =E13-D13 -> -460
A14: Permuta + projetos incentivados + outros | D14: 9798 | E14: 12096 | F14: =E14-D14 -> 2298
A15: Subtotal Recorrente | B15: =SUM(B5:B14) -> 26000 | C15: =SUM(C5:C14) -> 94000 | D15: =SUM(D5:D14) -> 309100 | E15: =SUM(E5:E14) -> 355853 | F15: =E15-D15 -> 46753
A17: PREMIAÇÕES E PARTICIPAÇÕES (EVENTUAIS)
A18: Copa Libertadores | D18: 194334 | E18: 31302 | F18: =E18-D18 -> -163032
A19: Mundial de Clubes FIFA | B19: 0 | C19: 0 | D19: 0 | E19: 147822
A20: Copa Intercontinental | D20: 9019 | E20: 0
A21: Copa do Brasil | D21: 5670 | E21: 10694 | F21: =E21-D21 -> 5024
A22: Brasileirão (premiação) | D22: 48166 | E22: 67498 | F22: =E22-D22 -> 19332
A23: Supercopa | B23: 0 | C23: 0 | D23: 0 | E23: 6050
A24: Recopa | B24: 0 | C24: 0 | D24: 0 | E24: 5241
A25: Outros (Feminino, etc) | D25: 315 | E25: 483 | F25: =E25-D25 -> 168
A26: Subtotal Premiações | B26: =SUM(B18:B25) -> 0 | C26: =SUM(C18:C25) -> 0 | D26: =SUM(D18:D25) -> 257504 | E26: =SUM(E18:E25) -> 269090 | F26: =E26-D26 -> 11586
A28: BILHETERIA
A29: Bilheteria total | D29: 36356 | E29: 17494 | F29: =E29-D29 -> -18862
A31: CESSÃO DE ATLETAS — RECEITAS
A32: Cessão temporária + solidariedade (em rec operacional) | D32: 4362 | E32: 12596 | F32: =E32-D32 -> 8234
A33: Cessão definitiva (fora da rec operacional) | B33: 4000 | C33: 77000 | D33: 96356 | E33: 733361 | F33: =E33-D33 -> 637005
A34: Subtotal Cessão Atletas | B34: =B32+B33 -> 4000 | C34: =C32+C33 -> 77000 | D34: =D32+D33 -> 100718 | E34: =E32+E33 -> 745957 | F34: =E34-D34 -> 645239
A36: TOTAIS
A37: Receita Operacional Bruta (sem cessão definitiva) | B37: =B15+B26+IFERROR(B29,0)+B32 -> 26000 | C37: =C15+C26+IFERROR(C29,0)+C32 -> 94000 | D37: =D15+D26+IFERROR(D29,0)+D32 -> 607322 | E37: =E15+E26+IFERROR(E29,0)+E32 -> 655033 | F37: =E37-D37 -> 47711
A38: Receita Total com Cessão Definitiva | B38: =B37+B33 -> 30000 | C38: =C37+C33 -> 171000 | D38: =D37+D33 -> 703678 | E38: =E37+E33 -> 1388394 | F38: =E38-D38 -> 684716
A40: TESTES CONTRAFACTUAIS — 2024 e 2025
A41: Receita 2025 sem Mundial de Clubes | E41: =E37-E19 -> 507211
A42: Receita 2025 sem Mundial nem Libertadores | E42: =E37-E19-E18 -> 475909
A43: Δ Receita recorrente pura 2025 vs 2024 (R$) | E43: =E15-D15 -> 46753
A44: Δ Receita recorrente pura 2025 vs 2024 (%) | E44: =IFERROR(E15/D15-1,"-") -> 0.15125526
A46: Notas:
A47: (1) 2022-2023: dados parciais via charts do Relatório de Gestão 2025. Algumas linhas combinadas onde detalhe não disponível.
...

Sheet DFC
A1: DEMONSTRAÇÃO DOS FLUXOS DE CAIXA — CONTROLADORA (R$ mil)
A2: Linha | B2: 2023 reapres | C2: 2024 reapres | D2: 2025 | E2: Δ 2025 vs 2024r
A4: ATIVIDADES OPERACIONAIS
A5: Prejuízo do exercício | B5: -56037 | C5: -266817 | D5: -290898 | E5: =D5-C5 -> -24081
A6: Ajuste de exercícios anteriores | B6: 66381 | C6: -11568 | D6: 1 | E6: =D6-C6 -> 11569
A7: Depreciação e amortização | B7: 92574 | C7: 132676 | D7: 242815 | E7: =D7-C7 -> 110139
A8: Baixa de imobilizado | B8: 0 | C8: 78 | D8: 2 | E8: =D8-C8 -> -76
A9: Baixa de atletas | B9: 16352 | C9: 39741 | D9: 337396 | E9: =D9-C9 -> 297655
A10: Atualização monetária | B10: -2266 | C10: 4757 | D10: -57419 | E10: =D10-C10 -> -62176
A11: Ajuste a valor presente | B11: 0 | C11: 405 | D11: 685 | E11: =D11-C11 -> 280
A12: Diferença de variação cambial líquida | B12: 1944 | C12: 11353 | D12: -20035 | E12: =D12-C12 -> -31388
A13: Depreciação de arrendamento (direito de uso) | B13: 2074 | C13: 3925 | D13: 4770 | E13: =D13-C13 -> 845
A14: Equivalência patrimonial | B14: 0 | C14: 6509 | D14: 6544 | E14: =D14-C14 -> 35
A15: Subtotal — Ajustes não-caixa (inclui prejuízo) | B15: =SUM(B5:B14) -> 121022 | C15: =SUM(C5:C14) -> -78941 | D15: =SUM(D5:D14) -> 223861 | E15: =D15-C15 -> 302802
A17: VARIAÇÃO DE WORKING CAPITAL
A18: Δ Contas a receber | B18: 857 | C18: -43706 | D18: 47121 | E18: =D18-C18 -> 90827
A19: Δ Estoque | B19: -4524 | C19: 1723 | D19: -16622 | E19: =D19-C19 -> -18345
A20: Δ Impostos a recuperar | B20: -2015 | C20: -222 | D20: 12 | E20: =D20-C20 -> 234
A21: Δ Outros ativos | B21: 780 | C21: 1885 | D21: -5100 | E21: =D21-C21 -> -6985
A22: Δ Investimentos | B22: 0 | C22: -21948 | D22: 0 | E22: =D22-C22 -> 21948
A23: Δ Adiantamentos ativos | B23: -367 | C23: -1056 | D23: 947 | E23: =D23-C23 -> 2003
A24: Δ Despesas antecipadas | B24: -539 | C24: -2984 | D24: -9912 | E24: =D24-C24 -> -6928
A25: Δ Fornecedores e contas a pagar | B25: -174682 | C25: 537754 | D25: 571455 | E25: =D25-C25 -> 33701
A26: Δ Adiantamentos passivos | B26: 0 | C26: 0 | D26: 850 | E26: =D26-C26 -> 850
A27: Δ Obrigações sociais e trabalhistas | B27: 14291 | C27: 54358 | D27: -46262 | E27: =D27-C27 -> -100620
A28: Δ Obrigações tributárias | B28: 74183 | C28: 178714 | D28: 291919 | E28: =D28-C28 -> 113205
A29: Δ Provisão para contingências | B29: 4251 | C29: 14090 | D29: 8364 | E29: =D29-C29 -> -5726
A30: Δ Receita diferida | B30: -81215 | C30: 345849 | D30: -187750 | E30: =D30-C30 -> -533599
A31: Subtotal — Variação de WC | B31: =SUM(B18:B30) -> -168980 | C31: =SUM(C18:C30) -> 1064457 | D31: =SUM(D18:D30) -> 655022 | E31: =D31-C31 -> -409435
A32: Caixa gerado nas operações | B32: =B15+B31 -> -47958 | C32: =C15+C31 -> 985516 | D32: =D15+D31 -> 878883 | E32: =D32-C32 -> -106633
A33: Impostos pagos | B33: -24490 | C33: -42794 | D33: -72115 | E33: =D33-C33 -> -29321
A34: Juros pagos | B34: -19996 | C34: -37588 | D34: -38390 | E34: =D34-C34 -> -802
A35: CAIXA LÍQUIDO DAS ATIVIDADES OPERACIONAIS | B35: =B32+B33+B34 -> -92444 | C35: =C32+C33+C34 -> 905134 | D35: =D32+D33+D34 -> 768378 | E35: =D35-C35 -> -136756
A37: ATIVIDADES DE INVESTIMENTO
A38: Mútuo com partes relacionadas | B38: -505745 | C38: -87543 | D38: -35322 | E38: =D38-C38 -> 52221
A39: Aquisição de Ativo de Direito de Uso | B39: 1588 | C39: 6071 | D39: 833 | E39: =D39-C39 -> -5238
A40: Aquisições do Imobilizado | B40: -10547 | C40: -5198 | D40: -28506 | E40: =D40-C40 -> -23308
A41: Aquisições do Intangível | B41: -77676 | C41: -534576 | D41: -869962 | E41: =D41-C41 -> -335386
A42: CAIXA LÍQUIDO DAS ATIVIDADES DE INVESTIMENTO | B42: =SUM(B38:B41) -> -592380 | C42: =SUM(C38:C41) -> -621246 | D42: =SUM(D38:D41) -> -932957 | E42: =D42-C42 -> -311711
A44: ATIVIDADES DE FINANCIAMENTO
...

Sheet Operacional Puro
A1: EBITDA RECORRENTE PURO — RECONCILIAÇÃO 2022-2025 (R$ mil)
A2: A operação recorrente da SAF nunca foi positiva em 4 anos.
A3: Linha | B3: 2022 | C3: 2023 reapres | D3: 2024 reapres | E3: 2025
A5: PARTIDA: RESULTADO OPERACIONAL ANTES DA ALIENAÇÃO
A6: Resultado Operacional Antes da Alienação de Ativos | B6: -235491 | C6: =DRE!B13 -> -18309 | D6: =DRE!C13 -> -160119 | E6: =DRE!D13 -> -274066
A8: AJUSTES PARA EBITDA RECORRENTE PURO
A9: (+) Depreciação e amortização (D&A pura) | B9: 81286 | C9: 94648 | D9: 132676 | E9: 247585
A10: (−) LFU 20% 2023 (não-recorrente) | B10: 0 | C10: -165000 | D10: 0 | E10: 0
A11: (−) Recuperação de gastos 2025 (não-recorrente) | B11: 0 | C11: 0 | D11: 0 | E11: 0
A12: (+/−) Outros ajustes auxiliares | B12: 0 | C12: 0 | D12: 0 | E12: 0
A14: EBITDA RECORRENTE PURO | B14: =B6+B9+B10+B11+B12 -> -154205 | C14: =C6+C9+C10+C11+C12 -> -88661 | D14: =D6+D9+D10+D11+D12 -> -27443 | E14: =E6+E9+E10+E11+E12 -> -26481
A16: CONTEXTUALIZAÇÃO
A17: Receita operacional líquida | B17: 143000 | C17: =DRE!B6 -> 279197 | D17: =DRE!C6 -> 552271 | E17: =DRE!D6 -> 574006
A18: Margem EBITDA recorrente puro | B18: =IFERROR(B14/B17,"-") -> -1.0783566 | C18: =IFERROR(C14/C17,"-") -> -0.31755714 | D18: =IFERROR(D14/D17,"-") -> -0.049691184 | E18: =IFERROR(E14/E17,"-") -> -0.046133664
A19: YoY EBITDA recorrente puro (Δ R$) | C19: =C14-B14 -> 65544 | D19: =D14-C14 -> 61218 | E19: =E14-D14 -> 962
A21: CHECAGEM CRUZADA — EBITDA REPORTADO → PURO
A22: EBITDA reportado pelo clube (consolidado) | B22: -154205 | C22: 198213 | D22: 80915 | E22: 603799
A23: (−) Lucro líquido cessão atletas | B23: 0 | C23: -39778 | D23: -50524 | E23: -284518
A24: (+/−) Ajustes auxiliares (LFU 2023, recuperação 2025) | B24: 0 | C24: -165000 | D24: 0 | E24: 0
A25: EBITDA recorrente puro — cálculo cruzado | B25: =B22+B23+B24 -> -154205 | C25: =C22+C23+C24 -> -6565 | D25: =D22+D23+D24 -> 30391 | E25: =E22+E23+E24 -> 319281
A27: Notas metodológicas:
A28: (1) D&A pura = depreciação + amortização (atletas em posse + intangíveis técnicos + arrendamento). EXCLUI baixa de atletas vendidos (parte do custo de cessão).
A29: (2) Recuperação de gastos R$ 50,5 MM em 2025 = reversão de provisões com atletas e intermediários (nota 23.1). Não-recorrente — ajusta para baixo.
A30: (3) 2023 reapres: "Outras receitas operacionais" inclui R$ 165 MM da venda LFU 20% (Brasileirão Holdings). Sem isso, EBITDA recorrente 2023 = -R$ 91 MM.
A31: (4) EBITDA reportado 2025 R$ 604 MM é tecnicamente correto mas inclui R$ 733 MM de receita cessão sem subtrair R$ 337 MM de baixa de atletas vendidos.
A32: (5) Conclusão: EBITDA recorrente puro nunca foi positivo em 4 anos. Melhora em 2025 é puxada por (a) cessão de atletas e (b) reversões não-recorrentes.

Sheet Indicadores
A1: INDICADORES FINANCEIROS — SÍNTESE (R$ mil ou %, conforme indicado)
A2: Indicador | B2: 2023 reapres | C2: 2024 reapres | D2: 2025 | E2: Critério/Bench
A4: 1. LIQUIDEZ
A5: Capital Circulante Líquido (AC − PC) | B5: =BP!B13-BP!B35 -> -215983 | C5: =BP!C13-BP!C35 -> -549048 | D5: =BP!D13-BP!D35 -> -952032 | E5: Deve ser > 0
A6: Liquidez Corrente (AC / PC) | B6: =IFERROR(BP!B13/BP!B35,"-") -> 0.68997003 | C6: =IFERROR(BP!C13/BP!C35,"-") -> 0.54621582 | D6: =IFERROR(BP!D13/BP!D35,"-") -> 0.29666407 | E6: ≥ 1,0x
A7: Liquidez Imediata (Caixa / PC) | B7: =IFERROR(BP!B6/BP!B35,"-") -> 0.023048811 | C7: =IFERROR(BP!C6/BP!C35,"-") -> 0.10657706 | D7: =IFERROR(BP!D6/BP!D35,"-") -> 0.018880832 | E7: ≥ 0,10x
A8: Caixa / (Fornecedores CP + Empréstimos CP) | B8: =IFERROR(BP!B6/(BP!B27+BP!B28),"-") -> 0.030228071 | C8: =IFERROR(BP!C6/(BP!C27+BP!C28),"-") -> 0.2442647 | D8: =IFERROR(BP!D6/(BP!D27+BP!D28),"-") -> 0.026372082 | E8: ≥ 10%
A10: 2. ENDIVIDAMENTO
A11: Dívida total bruta (Empréstimos CP + LP) | B11: =BP!B28+BP!B38 -> 377592 | C11: =BP!C28+BP!C38 -> 48112 | D11: =BP!D28+BP!D38 -> 138972 | E11: —
A12: Dívida líquida (bruta − caixa) | B12: =BP!B28+BP!B38-BP!B6 -> 361535 | C12: =BP!C28+BP!C38-BP!C6 -> -80839 | D12: =BP!D28+BP!D38-BP!D6 -> 113415 | E12: —
A13: Passivo Total / Ativo Total | B13: =IFERROR(BP!B44/BP!B23,"-") -> 1.0350553 | C13: =IFERROR(BP!C44/BP!C23,"-") -> 1.0989794 | D13: =IFERROR(BP!D44/BP!D23,"-") -> 1.2726002 | E13: ≤ 70%
A14: PL / Ativo Total | B14: =IFERROR(BP!B50/BP!B23,"-") -> -0.035055283 | C14: =IFERROR(BP!C50/BP!C23,"-") -> -0.098980852 | D14: =IFERROR(BP!D50/BP!D23,"-") -> -0.27260018 | E14: > 0%
A15: Fornecedores totais / Receita Operacional Bruta | B15: =IFERROR((BP!B27+BP!B37)/DRE!B4,"-") -> 0.56151416 | C15: =IFERROR((BP!C27+BP!C37)/DRE!C4,"-") -> 1.066925 | D15: =IFERROR((BP!D27+BP!D37)/DRE!D4,"-") -> 1.7824583 | E15: < 50%
A17: 3. OPERACIONAL
A18: Margem bruta | B18: =IFERROR(DRE!B8/DRE!B6,"-") -> -0.34254308 | C18: =IFERROR(DRE!C8/DRE!C6,"-") -> -0.10196624 | D18: =IFERROR(DRE!D8/DRE!D6,"-") -> -0.1763884 | E18: > 0%
A19: Margem op antes alienação | B19: =IFERROR(DRE!B13/DRE!B6,"-") -> -0.065577352 | C19: =IFERROR(DRE!C13/DRE!C6,"-") -> -0.28992831 | D19: =IFERROR(DRE!D13/DRE!D6,"-") -> -0.47746191 | E19: > 0%
A20: Margem EBITDA recorrente puro | B20: =IFERROR('Operacional Puro'!C14/DRE!B6,"-") -> -0.31755714 | C20: =IFERROR('Operacional Puro'!D14/DRE!C6,"-") -> -0.049691184 | D20: =IFERROR('Operacional Puro'!E14/DRE!D6,"-") -> -0.046133664 | E20: ≥ +5%
A21: Margem líquida | B21: =IFERROR(DRE!B18/DRE!B6,"-") -> -0.20070774 | C21: =IFERROR(DRE!C18/DRE!C6,"-") -> -0.48312694 | D21: =IFERROR(DRE!D18/DRE!D6,"-") -> -0.50678564 | E21: > 0%
A22: Capex atletas / Receita cessão atletas | B22: =IFERROR(-DFC!B41/DRE!B14,"-") -> 1.0087792 | C22: =IFERROR(-DFC!C41/DRE!C14,"-") -> 5.5479264 | D22: =IFERROR(-DFC!D41/DRE!D14,"-") -> 1.1862671 | E22: ≤ 1,0x
A24: 4. FOLHA AMPLIADA
A25: Salários, encargos e benefícios (custos + DGA) | B25: 130000 | C25: 357511 | D25: 335978
A26: Direitos de imagem (custos + DGA) | B26: 30000 | C26: 82501 | D26: 102163
A27: Folha ampliada total | B27: =SUM(B25:B26) -> 160000 | C27: =SUM(C25:C26) -> 440012 | D27: =SUM(D25:D26) -> 438141
A28: Folha ampliada / Receita Líquida | B28: =IFERROR(B27/DRE!B6,"-") -> 0.57307206 | C28: =IFERROR(C27/DRE!C6,"-") -> 0.79673204 | D28: =IFERROR(D27/DRE!D6,"-") -> 0.76330387 | E28: ≤ 65%
A29: Folha ampliada / Receita Op Bruta | B29: =IFERROR(B27/DRE!B4,"-") -> 0.51275149 | C29: =IFERROR(C27/DRE!C4,"-") -> 0.72451187 | D29: =IFERROR(D27/DRE!D4,"-") -> 0.66888386 | E29: ≤ 65%
A31: 5. GERAÇÃO DE CAIXA
A32: Caixa op puro (excl. WC, R$ mil) | B32: =DFC!B35 -> -92444 | C32: =DFC!C35 -> 905134 | D32: =DFC!D35 -> 768378 | E32: Linkado DFC
A33: Aporte do controlador (R$ mil) | B33: =DFC!B66 -> 0 | C33: =DFC!C66 -> 0 | D33: =DFC!D66 -> 0 | E33: —
A34: Capex intangível (atletas, R$ mil) | B34: =DFC!B41 -> -77676 | C34: =DFC!C41 -> -534576 | D34: =DFC!D41 -> -869962 | E34: —
A36: Notas:
A37: (1) Folha ampliada 2023 estimada — detalhe não disponível nos prints. Valor pode subir para ~R$ 220 MM se incluir totais finos das notas explicativas.
A38: (2) Liquidez Corrente caiu de 0,69x (2023r) → 0,77x (2024r) → 0,15x (2025). Deterioração severa em 1 ano.
A39: (3) Caixa op puro -R$ 431 MM em 2025 = clube precisaria de R$ 36 MM/mês de aporte só para empatar fluxo operacional.

Sheet Premissas Runway
A1: PREMISSAS RUNWAY 2026-2027 — 3 CENÁRIOS
A2: Todas as premissas em azul são editáveis. Aporte = R$ 0 em TODOS os cenários (premissa firme).
A3: Premissa | B3: Otimista | C3: Base | D3: Pessimista
A5: PREMISSAS DE PARTIDA (base 2025)
A6: Receita operacional bruta 2025 (link DRE) | B6: =DRE!D4 -> 655033 | C6: =DRE!D4 -> 655033 | D6: =DRE!D4 -> 655033
A7: (−) Mundial de Clubes 2025 (não-recorrente) | B7: -147822 | C7: -147822 | D7: -147822
A8: (−) Libertadores 2025 (não-recorrente parcial) | B8: 0 | C8: -15000 | D8: -31302
A9: Receita recorrente base normalizada | B9: =B6+B7+B8 -> 507211 | C9: =C6+C7+C8 -> 492211 | D9: =D6+D7+D8 -> 475909
A11: CRESCIMENTO E DESEMPENHO ESPORTIVO 2026
A12: Crescimento receita recorrente 2026 vs base | B12: 0.05 | C12: 0.03 | D12: -0.05
A13: Premiação esportiva esperada 2026 (Libertadores + Brasileirão) | B13: 180000 | C13: 90000 | D13: 30000
A14: Crescimento receita recorrente 2027 vs 2026 | B14: 0.1 | C14: 0.04 | D14: -0.03
A15: Premiação esportiva esperada 2027 | B15: 200000 | C15: 100000 | D15: 35000
A17: CESSÃO DE ATLETAS
A18: Receita cessão atletas 2026 (venda massiva para fechar o ano) | B18: 700000 | C18: 500000 | D18: 350000
A19: Receita cessão atletas 2027 (pós-RJ; transfer bans caindo) | B19: 400000 | C19: 250000 | D19: 100000
A20: Custo cessão / receita cessão (histórico ~60%) | B20: 0.55 | C20: 0.6 | D20: 0.65
A22: CUSTOS OPERACIONAIS
A23: Folha ampliada base 2025 (link Indicadores) | B23: =Indicadores!D27 -> 438141 | C23: =Indicadores!D27 -> 438141 | D23: =Indicadores!D27 -> 438141
A24: Redução de folha planejada 2026 (sob RJ) | B24: -0.15 | C24: -0.1 | D24: 0
A25: Variação folha 2027 vs 2026 | B25: -0.05 | C25: 0.05 | D25: 0.1
A26: Outros custos op. (% da receita recorrente, ex-folha) | B26: 0.35 | C26: 0.4 | D26: 0.45
A28: INVESTIMENTO EM ATLETAS
A29: Capex atletas 2026 (limite RJ — bem inferior a 2025) | B29: 200000 | C29: 150000 | D29: 50000
A30: Capex atletas 2027 (transfer bans caindo) | B30: 300000 | C30: 200000 | D30: 100000
A32: FINANCEIRO
A33: Despesa financeira recorrente 2026 (R$ mil) | B33: -180000 | C33: -200000 | D33: -280000
A34: Despesa financeira recorrente 2027 (R$ mil) | B34: -150000 | C34: -150000 | D34: -250000
A36: CAIXA INICIAL
A37: Caixa inicial 31/12/2025 (link BP) | B37: =BP!D6 -> 25557 | C37: =BP!D6 -> 25557 | D37: =BP!D6 -> 25557
A38: Aporte de capital novo (TODOS os cenários) | B38: 0 | C38: 0 | D38: 0
A40: CÂMBIO
A41: R$ / EUR | B41: 5.8 | C41: 5.8 | D41: 5.8
A43: Notas:
A44: (1) Aporte = R$ 0 em TODOS os cenários por premissa firme do post: a tese estuda a SAF sem o controlador.
A45: (2) Cenário Otimista assume Libertadores 2026 boa, RJ avança limpa, cessão massiva (R$ 700 MM, vende 2 estrelas). Sem possibilidade.
A46: (3) Cenário Base assume desempenho mediano + RJ com prazos + cessão R$ 500 MM (3-4 jogadores vendidos a preço razoável).
A47: (4) Cenário Pessimista assume queda esportiva + RJ travada + cessão R$ 350 MM (preço comprimido + transfer bans).
A48: (5) Lyon NÃO é variável de cenário — entra como observação textual em Resumo Cenários. Impacto financeiro: ver Cenários Impairment.

Sheet Modelo Runway
A1: MODELO RUNWAY — 3 CENÁRIOS × 2026 + 2027 (R$ mil)
A2: Aporte de capital = R$ 0 em todos os cenários. Lyon como observação textual em Resumo Cenários.
B3: 2026 | E3: 2027
A4: Linha | B4: Otimista | C4: Base | D4: Pessim. | E4: Otimista | F4: Base | G4: Pessim.
A6: DRE SIMPLIFICADA — 2026 e 2027
A7: Receita recorrente | B7: ='Premissas Runway'!B9*(1+'Premissas Runway'!B12) -> 532571.55 | C7: ='Premissas Runway'!C9*(1+'Premissas Runway'!C12) -> 506977.33 | D7: ='Premissas Runway'!D9*(1+'Premissas Runway'!D12) -> 452113.55 | E7: =B7*(1+'Premissas Runway'!B14) -> 585828.71 | F7: =C7*(1+'Premissas Runway'!C14) -> 527256.42 | G7: =D7*(1+'Premissas Runway'!D14) -> 438550.14
A8: Premiação esportiva | B8: ='Premissas Runway'!B13 -> 180000 | C8: ='Premissas Runway'!C13 -> 90000 | D8: ='Premissas Runway'!D13 -> 30000 | E8: ='Premissas Runway'!B15 -> 200000 | F8: ='Premissas Runway'!C15 -> 100000 | G8: ='Premissas Runway'!D15 -> 35000
A9: Receita cessão atletas | B9: ='Premissas Runway'!B18 -> 700000 | C9: ='Premissas Runway'!C18 -> 500000 | D9: ='Premissas Runway'!D18 -> 350000 | E9: ='Premissas Runway'!B19 -> 400000 | F9: ='Premissas Runway'!C19 -> 250000 | G9: ='Premissas Runway'!D19 -> 100000
A10: Receita TOTAL | B10: =B7+B8+B9 -> 1412571.6 | C10: =C7+C8+C9 -> 1096977.3 | D10: =D7+D8+D9 -> 832113.55 | E10: =E7+E8+E9 -> 1185828.7 | F10: =F7+F8+F9 -> 877256.42 | G10: =G7+G8+G9 -> 573550.14
A11: Folha ampliada (custo) | B11: =-'Premissas Runway'!B23*(1+'Premissas Runway'!B24) -> -372419.85 | C11: =-'Premissas Runway'!C23*(1+'Premissas Runway'!C24) -> -394326.9 | D11: =-'Premissas Runway'!D23*(1+'Premissas Runway'!D24) -> -438141 | E11: =B11*(1+'Premissas Runway'!B25) -> -353798.86 | F11: =C11*(1+'Premissas Runway'!C25) -> -414043.25 | G11: =D11*(1+'Premissas Runway'!D25) -> -481955.1
A12: Outros custos operacionais (% receita rec) | B12: =-B7*'Premissas Runway'!B26 -> -186400.04 | C12: =-C7*'Premissas Runway'!C26 -> -202790.93 | D12: =-D7*'Premissas Runway'!D26 -> -203451.1 | E12: =-E7*'Premissas Runway'!B26 -> -205040.05 | F12: =-F7*'Premissas Runway'!C26 -> -210902.57 | G12: =-G7*'Premissas Runway'!D26 -> -197347.56
A13: Custo cessão atletas | B13: =-B9*'Premissas Runway'!B20 -> -385000 | C13: =-C9*'Premissas Runway'!C20 -> -300000 | D13: =-D9*'Premissas Runway'!D20 -> -227500 | E13: =-E9*'Premissas Runway'!B20 -> -220000 | F13: =-F9*'Premissas Runway'!C20 -> -150000 | G13: =-G9*'Premissas Runway'!D20 -> -65000
A14: Resultado operacional | B14: =B10+B11+B12+B13 -> 468751.66 | C14: =C10+C11+C12+C13 -> 199859.5 | D14: =D10+D11+D12+D13 -> -36978.547 | E14: =E10+E11+E12+E13 -> 406989.8 | F14: =F10+F11+F12+F13 -> 102310.61 | G14: =G10+G11+G12+G13 -> -170752.52
A15: Despesa financeira | B15: ='Premissas Runway'!B33 -> -180000 | C15: ='Premissas Runway'!C33 -> -200000 | D15: ='Premissas Runway'!D33 -> -280000 | E15: ='Premissas Runway'!B34 -> -150000 | F15: ='Premissas Runway'!C34 -> -150000 | G15: ='Premissas Runway'!D34 -> -250000
A16: RESULTADO LÍQUIDO PROJETADO | B16: =B14+B15 -> 288751.66 | C16: =C14+C15 -> -140.502 | D16: =D14+D15 -> -316978.55 | E16: =E14+E15 -> 256989.8 | F16: =F14+F15 -> -47689.391 | G16: =G14+G15 -> -420752.52
A18: PROJEÇÃO DE CAIXA (DFC SIMPLIFICADA)
A19: Caixa inicial | B19: ='Premissas Runway'!B37 -> 25557 | C19: ='Premissas Runway'!C37 -> 25557 | D19: ='Premissas Runway'!D37 -> 25557
A20: + Aporte capital novo | B20: ='Premissas Runway'!B38 -> 0 | C20: ='Premissas Runway'!C38 -> 0 | D20: ='Premissas Runway'!D38 -> 0 | E20: ='Premissas Runway'!B38 -> 0 | F20: ='Premissas Runway'!C38 -> 0 | G20: ='Premissas Runway'!D38 -> 0
A21: + Resultado op (proxy caixa) | B21: =B14+B15 -> 288751.66 | C21: =C14+C15 -> -140.502 | D21: =D14+D15 -> -316978.55 | E21: =E14+E15 -> 256989.8 | F21: =F14+F15 -> -47689.391 | G21: =G14+G15 -> -420752.52
A22: − Capex atletas | B22: =-'Premissas Runway'!B29 -> -200000 | C22: =-'Premissas Runway'!C29 -> -150000 | D22: =-'Premissas Runway'!D29 -> -50000 | E22: =-'Premissas Runway'!B30 -> -300000 | F22: =-'Premissas Runway'!C30 -> -200000 | G22: =-'Premissas Runway'!D30 -> -100000
A23: Caixa esperado fim do ano | B23: =B19+B20+B21+B22 -> 114308.66 | C23: =C19+C20+C21+C22 -> -124583.5 | D23: =D19+D20+D21+D22 -> -341421.55 | E23: =B23+E20+E21+E22 -> 71298.458 | F23: =C23+F20+F21+F22 -> -372272.89 | G23: =D23+G20+G21+G22 -> -862174.07
A25: INDICADORES POR CENÁRIO/ANO (uso na aba Caminho A)
A26: Folha ampliada / Receita rec (cond 1) | B26: =IFERROR(-B11/B7,"-") -> 0.69928604 | C26: =IFERROR(-C11/C7,"-") -> 0.77779987 | D26: =IFERROR(-D11/D7,"-") -> 0.96909504 | E26: =IFERROR(-E11/E7,"-") -> 0.60392885 | F26: =IFERROR(-F11/F7,"-") -> 0.78527871 | G26: =IFERROR(-G11/G7,"-") -> 1.0989738
A27: EBITDA recorrente puro proxy (cond 2) | B27: =B14-B9-B13 -> 153751.66 | C27: =C14-C9-C13 -> -140.502 | D27: =D14-D9-D13 -> -159478.55 | E27: =E14-E9-E13 -> 226989.8 | F27: =F14-F9-F13 -> 2310.6089 | G27: =G14-G9-G13 -> -205752.52
A28: Margem EBITDA recorrente puro (cond 2 %) | B28: =IFERROR(B27/B7,"-") -> 0.28869672 | C28: =IFERROR(C27/C7,"-") -> -0.00027713665 | D28: =IFERROR(D27/D7,"-") -> -0.35274003 | E28: =IFERROR(E27/E7,"-") -> 0.38746787 | F28: =IFERROR(F27/F7,"-") -> 0.0043823248 | G28: =IFERROR(G27/G7,"-") -> -0.46916533
A29: Capex atletas / Receita cessão atletas (cond 3) | B29: =IFERROR('Premissas Runway'!B29/B9,"-") -> 0.28571429 | C29: =IFERROR('Premissas Runway'!C29/C9,"-") -> 0.3 | D29: =IFERROR('Premissas Runway'!D29/D9,"-") -> 0.14285714 | E29: =IFERROR('Premissas Runway'!B30/E9,"-") -> 0.75 | F29: =IFERROR('Premissas Runway'!C30/F9,"-") -> 0.8 | G29: =IFERROR('Premissas Runway'!D30/G9,"-") -> 1
A30: Caixa fim do ano (cond 4 numerador) | B30: =B23 -> 114308.66 | C30: =C23 -> -124583.5 | D30: =D23 -> -341421.55 | E30: =E23 -> 71298.458 | F30: =F23 -> -372272.89 | G30: =G23 -> -862174.07
A31: Saídas op mensais (cond 4 denominador) | B31: =(-B11-B12-B15)/12 -> 61568.324 | C31: =(-C11-C12-C15)/12 -> 66426.486 | D31: =(-D11-D12-D15)/12 -> 76799.341 | E31: =(-E11-E12-E15)/12 -> 59069.909 | F31: =(-F11-F12-F15)/12 -> 64578.818 | G31: =(-G11-G12-G15)/12 -> 77441.889
A32: Cobertura caixa em meses (cond 4) | B32: =IFERROR(B30/B31,"-") -> 1.8566147 | C32: =IFERROR(C30/C31,"-") -> -1.8755094 | D32: =IFERROR(D30/D31,"-") -> -4.4456312 | E32: =IFERROR(E30/E31,"-") -> 1.2070183 | F32: =IFERROR(F30/F31,"-") -> -5.7646285 | G32: =IFERROR(G30/G31,"-") -> -11.133175
A34: Notas:
A35: (1) Modelo simplificado — DRE + caixa esquemático. Não substitui um budget completo, mas serve para teste das 4 condições.
A36: (2) Caixa fim 2027 reusa caixa fim 2026 como ponto de partida (running).
A37: (3) "EBITDA recorrente puro proxy" = Resultado op − receita cessão − custo cessão. Mesma lógica da aba Operacional Puro.
A38: (4) "Saídas op mensais" para cobertura caixa = (folha + outros + |dfin|)/12. Ignora capex atletas (considerado discricionário).

Sheet Resumo Cenários
A1: RESUMO CENÁRIOS — VISÃO CONSOLIDADA 2026-2027
A2: Item | B2: Otimista | C2: Base | D2: Pessimista
A4: RESULTADO LÍQUIDO PROJETADO (R$ mil)
A5: 2026 | B5: ='Modelo Runway'!B16 -> 288751.66 | C5: ='Modelo Runway'!C16 -> -140.502 | D5: ='Modelo Runway'!D16 -> -316978.55
A6: 2027 | B6: ='Modelo Runway'!E16 -> 256989.8 | C6: ='Modelo Runway'!F16 -> -47689.391 | D6: ='Modelo Runway'!G16 -> -420752.52
A7: Acumulado 2026-2027 | B7: =B5+B6 -> 545741.46 | C7: =C5+C6 -> -47829.893 | D7: =D5+D6 -> -737731.07
A9: CAIXA FIM DO ANO (R$ mil)
A10: Caixa final 2026 | B10: ='Modelo Runway'!B23 -> 114308.66 | C10: ='Modelo Runway'!C23 -> -124583.5 | D10: ='Modelo Runway'!D23 -> -341421.55
A11: Caixa final 2027 | B11: ='Modelo Runway'!E23 -> 71298.458 | C11: ='Modelo Runway'!F23 -> -372272.89 | D11: ='Modelo Runway'!G23 -> -862174.07
A12: Sinal — caixa final 2027 | B12: =IF(B11<0,"NEGATIVO","positivo") -> positivo | C12: =IF(C11<0,"NEGATIVO","positivo") -> NEGATIVO | D12: =IF(D11<0,"NEGATIVO","positivo") -> NEGATIVO
A14: RECEITA TOTAL PROJETADA (R$ mil)
A15: Receita total 2026 | B15: ='Modelo Runway'!B10 -> 1412571.6 | C15: ='Modelo Runway'!C10 -> 1096977.3 | D15: ='Modelo Runway'!D10 -> 832113.55
A16: Receita total 2027 | B16: ='Modelo Runway'!E10 -> 1185828.7 | C16: ='Modelo Runway'!F10 -> 877256.42 | D16: ='Modelo Runway'!G10 -> 573550.14
A18: NARRATIVA DOS CENÁRIOS
A19: Desempenho esportivo | B19: Libertadores avança; Brasileirão top 4 | C19: Mediano; Brasileirão top 8 | D19: Queda esportiva; zona neutra
A20: Trajetória da RJ | B20: Plano aprovado limpo com prazos viáveis | C20: Plano com deságios moderados | D20: RJ travada ou liquidação
A21: Transfer bans | B21: Resolvidos em 2026 | C21: Resolvidos parcial. em 2027 | D21: Não resolvidos
A22: Cessão atletas (R$ mil) | B22: 2026: 700.000 2027: 400.000 | C22: 2026: 500.000 2027: 250.000 | D22: 2026: 350.000 2027: 100.000
A23: Folha 2026 vs base | B23: −20% | C23: −10% | D23: mantida (sem corte)
A24: Premissa firme | B24: Aporte = R$ 0 | C24: Aporte = R$ 0 | D24: Aporte = R$ 0
A27: OBSERVAÇÃO TEXTUAL — DISPUTA LYON (variável independente)
A28: Cenário Lyon — SAF vence | B28: PL ajustado: R$ -542 MM (impairment 0%) | C28: Idem (mesma trajetória) | D28: Idem (mesma trajetória)
A29: Cenário Lyon — Acordo bilateral | B29: PL ajustado: R$ -1.196 MM (impairment 50% + 50% Lyon) | C29: Idem | D29: Idem
A30: Cenário Lyon — Lyon vence | B30: PL ajustado: R$ -1.834 MM (impairment 100% + Lyon integral) | C30: Idem | D30: Idem
A33: Notas:
A34: (1) Cenários macro (Otim/Base/Pess) modelam apenas operação e cessão atletas. A disputa Lyon entra como variável independente.
A35: (2) Para ver impacto patrimonial dos 3 sub-cenários Lyon (SAF ganha / Acordo / Lyon ganha), ver aba "Cenários Impairment".
A36: (3) Em TODOS os cenários, o aporte de capital novo é R$ 0 — premissa firme da análise.
A37: (4) Mesmo no Otimista, o caixa fim 2026 já fica negativo, indicando que a SAF precisará de fluxo extra (mais cessão ou refinanciamento) durante o ano.

Sheet Caminho A — Trajetória
A1: CAMINHO A — TRAJETÓRIA: 4 CONDIÇÕES × 3 CENÁRIOS × 2 ANOS
A2: Aplicação das 4 condições rigorosas de competitividade nos cenários 2026-2027. Históricos 2024r e 2025 incluídos para comparação.
A4: Condição | B4: Critério | C4: 2024r | D4: 2025 | E4: 2026 Otim | F4: 2026 Base | G4: 2026 Pess | H4: 2027 Otim | I4: 2027 Base | J4: 2027 Pess
A5: COND 1 — Folha | B5: Folha ampliada ≤ 65% RL | C5: =Indicadores!C28 -> 0.79673204 | D5: =Indicadores!D28 -> 0.76330387 | E5: ='Modelo Runway'!B26 -> 0.69928604 | F5: ='Modelo Runway'!C26 -> 0.77779987 | G5: ='Modelo Runway'!D26 -> 0.96909504 | H5: ='Modelo Runway'!E26 -> 0.60392885 | I5: ='Modelo Runway'!F26 -> 0.78527871 | J5: ='Modelo Runway'!G26 -> 1.0989738
A6: Status | C6: =IF(C5<=0.65,"OK","FALHA") -> FALHA | D6: =IF(D5<=0.65,"OK","FALHA") -> FALHA | E6: =IF(E5<=0.65,"OK","FALHA") -> FALHA | F6: =IF(F5<=0.65,"OK","FALHA") -> FALHA | G6: =IF(G5<=0.65,"OK","FALHA") -> FALHA | H6: =IF(H5<=0.65,"OK","FALHA") -> OK | I6: =IF(I5<=0.65,"OK","FALHA") -> FALHA | J6: =IF(J5<=0.65,"OK","FALHA") -> FALHA
A8: COND 2 — EBITDA | B8: Margem EBITDA recor. ≥ +5% | C8: ='Operacional Puro'!D18 -> -0.049691184 | D8: ='Operacional Puro'!E18 -> -0.046133664 | E8: ='Modelo Runway'!B28 -> 0.28869672 | F8: ='Modelo Runway'!C28 -> -0.00027713665 | G8: ='Modelo Runway'!D28 -> -0.35274003 | H8: ='Modelo Runway'!E28 -> 0.38746787 | I8: ='Modelo Runway'!F28 -> 0.0043823248 | J8: ='Modelo Runway'!G28 -> -0.46916533
A9: Status | C9: =IF(C8>=0.05,"OK","FALHA") -> FALHA | D9: =IF(D8>=0.05,"OK","FALHA") -> FALHA | E9: =IF(E8>=0.05,"OK","FALHA") -> OK | F9: =IF(F8>=0.05,"OK","FALHA") -> FALHA | G9: =IF(G8>=0.05,"OK","FALHA") -> FALHA | H9: =IF(H8>=0.05,"OK","FALHA") -> OK | I9: =IF(I8>=0.05,"OK","FALHA") -> FALHA | J9: =IF(J8>=0.05,"OK","FALHA") -> FALHA
A11: COND 3 — Capex | B11: Capex atletas ≤ Receita cessão (≤ 1,0x) | C11: 5.5479264 | D11: 1.1862671 | E11: ='Modelo Runway'!B29 -> 0.28571429 | F11: ='Modelo Runway'!C29 -> 0.3 | G11: ='Modelo Runway'!D29 -> 0.14285714 | H11: ='Modelo Runway'!E29 -> 0.75 | I11: ='Modelo Runway'!F29 -> 0.8 | J11: ='Modelo Runway'!G29 -> 1
A12: Status | C12: =IF(C11<=1,"OK","FALHA") -> FALHA | D12: =IF(D11<=1,"OK","FALHA") -> FALHA | E12: =IF(E11<=1,"OK","FALHA") -> OK | F12: =IF(F11<=1,"OK","FALHA") -> OK | G12: =IF(G11<=1,"OK","FALHA") -> OK | H12: =IF(H11<=1,"OK","FALHA") -> OK | I12: =IF(I11<=1,"OK","FALHA") -> OK | J12: =IF(J11<=1,"OK","FALHA") -> OK
A14: COND 4 — Caixa | B14: Caixa final ≥ 1 mês de saídas op | C14: 2.082287 | D14: 0.32022871 | E14: ='Modelo Runway'!B32 -> 1.8566147 | F14: ='Modelo Runway'!C32 -> -1.8755094 | G14: ='Modelo Runway'!D32 -> -4.4456312 | H14: ='Modelo Runway'!E32 -> 1.2070183 | I14: ='Modelo Runway'!F32 -> -5.7646285 | J14: ='Modelo Runway'!G32 -> -11.133175
A15: Status | C15: =IF(C14>=1,"OK","FALHA") -> OK | D15: =IF(D14>=1,"OK","FALHA") -> FALHA | E15: =IF(E14>=1,"OK","FALHA") -> OK | F15: =IF(F14>=1,"OK","FALHA") -> FALHA | G15: =IF(G14>=1,"OK","FALHA") -> FALHA | H15: =IF(H14>=1,"OK","FALHA") -> OK | I15: =IF(I14>=1,"OK","FALHA") -> FALHA | J15: =IF(J14>=1,"OK","FALHA") -> FALHA
A17: SÍNTESE — VEREDITO POR CENÁRIO/ANO
A18: Condições atendidas (de 4) | C18: =COUNTIF(C6:C15,"OK") -> 1 | D18: =COUNTIF(D6:D15,"OK") -> 0 | E18: =COUNTIF(E6:E15,"OK") -> 3 | F18: =COUNTIF(F6:F15,"OK") -> 1 | G18: =COUNTIF(G6:G15,"OK") -> 1 | H18: =COUNTIF(H6:H15,"OK") -> 4 | I18: =COUNTIF(I6:I15,"OK") -> 1 | J18: =COUNTIF(J6:J15,"OK") -> 1
A19: Veredito | C19: =IF(C18=4,"COMPETITIVO",IF(C18>=2,"FRÁGIL","COLAPSO")) -> COLAPSO | D19: =IF(D18=4,"COMPETITIVO",IF(D18>=2,"FRÁGIL","COLAPSO")) -> COLAPSO | E19: =IF(E18=4,"COMPETITIVO",IF(E18>=2,"FRÁGIL","COLAPSO")) -> FRÁGIL | F19: =IF(F18=4,"COMPETITIVO",IF(F18>=2,"FRÁGIL","COLAPSO")) -> COLAPSO | G19: =IF(G18=4,"COMPETITIVO",IF(G18>=2,"FRÁGIL","COLAPSO")) -> COLAPSO | H19: =IF(H18=4,"COMPETITIVO",IF(H18>=2,"FRÁGIL","COLAPSO")) -> COMPETITIVO | I19: =IF(I18=4,"COMPETITIVO",IF(I18>=2,"FRÁGIL","COLAPSO")) -> COLAPSO | J19: =IF(J18=4,"COMPETITIVO",IF(J18>=2,"FRÁGIL","COLAPSO")) -> COLAPSO
A21: Notas:
A22: (1) Critérios novos (mais rigorosos): C1 folha ≤ 65% RL; C2 margem EBITDA ≥ +5%; C3 capex atletas ≤ receita cessão; C4 caixa ≥ 1 mês de saídas operacionais.
A23: (2) Histórico 2024r e 2025 incluído para baseline. Em 2025, todas as 4 condições falham → COLAPSO confirmado.
A24: (3) Mesmo no cenário Otimista 2026-2027, a SAF não atinge "COMPETITIVO" — o melhor caso é "FRÁGIL".
A25: (4) C2 (EBITDA) usa proxy do Modelo Runway: Resultado op − receita cessão − custo cessão (mesma lógica de Operacional Puro).
A26: (5) C4 histórico calculado com saídas op = (folha + DGA + |dfin|)/12. Em 2025: 0,3 meses de cobertura.
A27: (6) Interpretação: em 8 testes (2 anos × 3 cenários + 2 anos históricos), apenas 1 caso atinge COMPETITIVO (Otim 2027), e por margem estreita (caixa 1,2 meses; folha 60% RL). Os outros 7 são COLAPSO ou FRÁGIL — confirmando que o equilíbrio operacional da SAF exige uma trajetória otimista sustentada por 2 anos consecutivos, sem aporte e sem deslizes esportivos.

Sheet Anx — Suporte Controlador
B2: SUPORTE DO CONTROLADOR — PILARES E DESMONTE
B3: Os quatro canais paralelos de 2024 (R$ 1,2 BI) e o desmonte em 2025
B5: Mecanismo / Pilar | C5: 2022 | D5: 2023 reapres | E5: 2024 | F5: 2025
B6: PILAR 1 — APORTE DE CAPITAL FORMAL EAGLE
B7: Integralização de capital no exercício | C7: 81628 | D7: 102228 | E7: 166166 | F7: 0
B8: Saldo cumulativo do compromisso (R$ 350 MM) | C8: 81628 | D8: 183856 | E8: 350022 | F8: 350022
B9: Acordo cumprido? | C9: =IF(C8>=350000,"Sim","Em curso") -> Em curso | D9: =IF(D8>=350000,"Sim","Em curso") -> Em curso | E9: =IF(E8>=350000,"Sim","Em curso") -> Sim | F9: =IF(F8>=350000,"Sim","Em curso") -> Sim
B11: PILAR 2 — OPERAÇÃO OL SASU €56,4 MM (RECEITA DIFERIDA)
B12: Receita diferida cessão definitiva — saldo final | C12: 0 | D12: 0 | E12: 379283 | F12: 108397
B13: Caixa antecipado pela operação (cumulativo) | C13: 0 | D13: 0 | E13: 362000 | F13: 91000
B14: Câmbio efetivo implícito (R$/€) | E14: =E12/56400 -> 6.7248759 | F14: =F12/17350 -> 6.2476657
B16: PILAR 3 — QUITAÇÃO XP PELO TEXTOR PF + ATUALIZAÇÃO MONETÁRIA
B17: Empréstimo XP (saldo a pagar) | C17: 0 | D17: 333000 | E17: 0 | F17: 0
B18: Quitação Textor PF no ano (R$) | C18: 0 | D18: 0 | E18: 547000 | F18: 0
B19: Atualização monetária reconhecida em receita financeira | C19: 0 | D19: 0 | E19: 54707 | F19: -57419
B21: PILAR 4 — FINANCIAMENTO ESTRUTURADO COM GARANTIA SAF/OL
B22: Saldo BTG/OL LTDA (em mora 15/12/2024) | C22: 0 | D22: 0 | E22: 67700 | F22: 0
B23: Saldo Oliveira Trust (substitui BTG, garantia LFU) | C23: 0 | D23: 0 | E23: 0 | F23: 80673
B24: Total dívida estruturada com garantia cruzada | C24: =C22+C23 -> 0 | D24: =D22+D23 -> 0 | E24: =E22+E23 -> 67700 | F24: =F22+F23 -> 80673
B26: PILAR 5 — GARANTIAS OCULTAS LYON (revelado em 12/05/2026)
B27: Garantia oculta OL SASU sob lei inglesa (€30 MM, abr/2025) | C27: 0 | D27: 0 | E27: 0 | F27: 174000
B28: Crédito Lyon contra Botafogo (publicado 12/05/2026) | C28: 0 | D28: 0 | E28: 0 | F28: 727000
B29: Taxa de antecipação cumulativa (R$) | C29: 0 | D29: 6000 | E29: 130000 | F29: 141000
B31: SOMA DE SUPORTE DO CONTROLADOR — VISÃO ANUAL
B32: Aporte direto (pilar 1) | C32: =C7 -> 81628 | D32: =D7 -> 102228 | E32: =E7 -> 166166 | F32: =F7 -> 0
B33: Caixa via receita diferida (pilar 2) | C33: =C13 -> 0 | D33: =D13 -> 0 | E33: =E13 -> 362000 | F33: =F13 -> 91000
B34: Quitação dívida bancária (pilar 3) | C34: =C18 -> 0 | D34: =D18 -> 0 | E34: =E18 -> 547000 | F34: =F18 -> 0
B35: Saldo dívida estruturada criada no ano (pilar 4) | C35: =C24 -> 0 | D35: =D24 -> 0 | E35: =E24 -> 67700 | F35: =F24 -> 80673
B36: TOTAL SUPORTE ESTRUTURADO NO ANO | C36: =C32+C33+C34+C35 -> 81628 | D36: =D32+D33+D34+D35 -> 102228 | E36: =E32+E33+E34+E35 -> 1142866 | F36: =F32+F33+F34+F35 -> 171673
B38: LEITURA RETROSPECTIVA — DESMONTE EM 2025
B39: Pilar 1 (aporte): situação | F39: ZERADO — sem aporte em 2025
B40: Pilar 2 (Lyon): situação | F40: PARCIALMENTE DESMONTADO — Lyon publicou contraclaim
B41: Pilar 3 (XP/atualização): situação | F41: REVERTIDO — atualização virou despesa R$ 57 MM
B42: Pilar 4 (estruturada): situação | F42: SUBSTITUÍDO — BTG/OL → Oliveira Trust/LFU
B43: Pilar 5 (garantia oculta): situação | F43: EXPOSTO — garantia oculta abr/2025 revelada
B46: Notas:
B47: (1) Pilar 1: compromisso original era R$ 350 MM em 36 meses. Cumprido integralmente em 2024. Em 2025 não havia obrigação contratual residual.
B48: (2) Pilar 2: operação Lyon de €56,4 MM em 2024 virou €17,35 MM em 2025 (€9,75 MM Atlético Madrid + €7,6 MM Lyon residual). Câmbio implícito 2024: ~6,72 R$/€.
B49: (3) Pilar 3: quitação XP de R$ 547 MM em 2024 + R$ 54,7 MM em atualização monetária = neutralização contábil. Em 2025, atualização virou DESPESA de R$ 57 MM.
B50: (4) Pilar 4: arquitetura idêntica em 3 anos consecutivos (XP/Textor → BTG/OL LTDA → Oliveira Trust/LFU). Substituição do canal de financiamento estruturado.
...

Sheet Anx — Garantias e Factoring
B2: GARANTIAS CRUZADAS, FACTORING E ANTECIPAÇÃO DE RECEBÍVEIS
B3: O 5º pilar do suporte ao controlador — operações de risco compartilhado
B5: Operação | C5: Período | D5: Estrutura | E5: Valor R$ mil | F5: Status / Observação
B6: CANAL ESTRUTURADO COM GARANTIA SAF
B7: Empréstimo XP / cessão Textor PF | C7: jul/2023 | D7: Cessão fiduciária recebíveis SAF | E7: 333000 | F7: Quitado em 2024 por Textor PF
B8: Quitação XP — pagamento Textor PF | C8: 2024 | D8: Liquidação + atualização monetária | E8: 547000 | F8: R$ 54,7 MM de atualização contábil
B9: Notas Comerciais BTG / OL LTDA | C9: fev/2024 | D9: Garantia real + cessão fiduciária SAF | E9: 121500 | F9: Renegociado até dez/2024
B10: Saldo BTG em mora (15/12/2024) | C10: 31/12/2024 | D10: Inadimplência objetiva | E10: 67700 | F10: Refinanciado via Oliveira Trust em 2025
B11: Oliveira Trust | C11: 2025 | D11: Cessão fiduciária recebíveis LFU | E11: 80673 | F11: Vencimento 27/03/2028 — saldo em 31/12/2025
B13: GARANTIAS OCULTAS LYON (REVELADAS 12/05/2026)
B14: Garantia oculta OL SASU (lei inglesa) | C14: abr/2025 | D14: OL SASU como garantidor não-aprovado | E14: 174000 | F14: €30 MM — conselho do Lyon não aprovou
B15: Factoring / cessão de recebíveis | C15: 2024-2025 | D15: Garantias cruzadas Eagle (não-divulgadas) | F15: Magnitude exata desconhecida — Lyon questiona
B17: CUSTO FINANCEIRO DESSAS OPERAÇÕES (taxa de antecipação)
B18: Taxa de antecipação 2023 | C18: 2023 | D18: DRE - despesa financeira | E18: 6000 | F18: Linha embrionária
B19: Taxa de antecipação 2024 | C19: 2024 | D19: DRE - despesa financeira | E19: 130123 | F19: Salto de 22x
B20: Taxa de antecipação 2025 | C20: 2025 | D20: DRE - despesa financeira | E20: 141167 | F20: Mantida alta — 25% da receita líquida
B21: Acumulado 2023-2025 | D21: Custo financeiro total | E21: =SUM(E18:E20) -> 277290
B23: CROSS-CLAIMS ENTRE SAF E LYON
B24: SAF reivindica do Lyon (execução €104 MM) | C24: 03/04/2026 | D24: Ação execução título extrajudicial | E24: 603000 | F24: €104 MM × R$ 5,80/€
B25: Partes relacionadas ativo no balanço SAF | C25: 31/12/2025 | D25: Linha 7 do balanço | E25: 564683 | F25: Não-provisionado para impairment
B26: Lyon reivindica do Botafogo (balanço 12/05/2026) | C26: 12/05/2026 | D26: Crédito Lyon contra SAF | E26: 727000 | F26: Auditor cita R$ 732 MM (~mesmo valor)
B27: Diferença líquida — Lyon ganha | D27: Se Lyon vencer integralmente | E27: =-E25-E26 -> -1291683
B30: Notas:
B31: (1) Padrão arquitetural recorrente: SAF (ou entidade do grupo) toma empréstimo com garantia em recebíveis estratégicos do clube. Repetido 3x em 3 anos.
B32: (2) Taxa de antecipação acumulada de R$ 277 MM em 3 anos = 48% da receita líquida de 2025 em custos financeiros de operações de factoring/antecipação.
B33: (3) O auditor cita R$ 732.211 mil em "partes relacionadas passivo" no parecer — valor praticamente idêntico ao crédito que o Lyon publicou em 12/05/2026.
B34: (4) Magnitude exata das garantias cruzadas factoring é desconhecida — Lyon questiona "operações que nunca chegaram a se concretizar" mas serviram de lastro.

Sheet Anx — Cenários Impairment
B2: CENÁRIOS DE AJUSTE PATRIMONIAL — IMPAIRMENT + DISPUTA LYON
B3: Quatro cenários de ajuste vs o balanço reportado pela SAF, com 3 sub-cenários para a disputa Lyon
B5: PREMISSAS-CHAVE (editáveis em azul)
B6: PL reportado SAF 2025 (controladora) | C6: -431917 | D6: do balanço auditado 2025
B7: Partes relacionadas ATIVO — saldo total (CP+LP) | C7: 564683 | D7: sujeito a impairment
B8: Lyon reivindica do Botafogo (publicado 12/05/2026) | C8: 727000 | D8: crédito do Lyon contra SAF
B9: Ajuste FFU R$ 110.427 mil (parecer auditor) | C9: 110427 | D9: recompra LFU mal-classificada
B10: Risco PERSE contingente (R$ ainda não-mensurável) | C10: 100000 | D10: estimativa para sensibilidade
B11: % impairment partes relacionadas (cenário central) | C11: 1 | D11: percentual aplicável
B14: Cenário | C14: Status quo | D14: C1: Impairment 100% | E14: C2: + FFU/PERSE | F14: C3: Lyon SAF ganha | G14: C3: Lyon — Acordo bilateral | H14: C3: Lyon — Lyon ganha
B15: PARTIDA — PL REPORTADO
B16: PL reportado SAF 31/12/2025 | C16: =$C$6 -> -431917 | D16: =$C$6 -> -431917 | E16: =$C$6 -> -431917 | F16: =$C$6 -> -431917 | G16: =$C$6 -> -431917 | H16: =$C$6 -> -431917
B18: AJUSTES SOBRE ATIVOS
B19: (-) Impairment partes relacionadas (sobre ativo) | C19: 0 | D19: =-$C$7*$C$11 -> -564683 | E19: =-$C$7*$C$11 -> -564683 | F19: =-$C$7*0 -> 0 | G19: =-$C$7*0.5 -> -282341.5 | H19: =-$C$7*$C$11 -> -564683
B20: (-) Ajuste FFU R$ 110 MM (transferência ativo→resultado) | C20: 0 | D20: 0 | E20: =-$C$9 -> -110427 | F20: =-$C$9 -> -110427 | G20: =-$C$9 -> -110427 | H20: =-$C$9 -> -110427
B21: Subtotal ajustes ativos | C21: =C19+C20 -> 0 | D21: =D19+D20 -> -564683 | E21: =E19+E20 -> -675110 | F21: =F19+F20 -> -110427 | G21: =G19+G20 -> -392768.5 | H21: =H19+H20 -> -675110
B23: AJUSTES SOBRE PASSIVOS (CONTRACLAIM LYON)
B24: (-) Reconhecimento contraclaim Lyon — perda | C24: 0 | D24: 0 | E24: 0 | F24: 0 | G24: =-$C$8*0.5 -> -363500 | H24: =-$C$8 -> -727000
B25: (-) PERSE contingente | C25: 0 | D25: 0 | E25: =-$C$10 -> -100000 | F25: =-$C$10 -> -100000 | G25: =-$C$10 -> -100000 | H25: =-$C$10 -> -100000
B26: Subtotal ajustes passivos | C26: =C24+C25 -> 0 | D26: =D24+D25 -> 0 | E26: =E24+E25 -> -100000 | F26: =F24+F25 -> -100000 | G26: =G24+G25 -> -463500 | H26: =H24+H25 -> -827000
B28: PL AJUSTADO POR CENÁRIO
B29: PL ajustado | C29: =C16+C21+C26 -> -431917 | D29: =D16+D21+D26 -> -996600 | E29: =E16+E21+E26 -> -1207027 | F29: =F16+F21+F26 -> -642344 | G29: =G16+G21+G26 -> -1288185.5 | H29: =H16+H21+H26 -> -1934027
B31: DELTA vs PL REPORTADO
B32: Δ R$ | C32: =C29-C16 -> 0 | D32: =D29-D16 -> -564683 | E32: =E29-E16 -> -775110 | F32: =F29-F16 -> -210427 | G32: =G29-G16 -> -856268.5 | H32: =H29-H16 -> -1502110
B33: Δ múltiplo de Capital Social | C33: =IFERROR(C29/-375309,"-") -> 1.1508304 | D33: =IFERROR(D29/-375309,"-") -> 2.6554119 | E33: =IFERROR(E29/-375309,"-") -> 3.2160886 | F33: =IFERROR(F29/-375309,"-") -> 1.7115071 | G33: =IFERROR(G29/-375309,"-") -> 3.4323331 | H33: =IFERROR(H29/-375309,"-") -> 5.1531591
B34: Cobertura por Capital Social (R$ 375 MM) | C34: =IFERROR(MAX(0,C29+375309)/375309,IF(C29<-375309,"DEFICITÁRIO","OK")) -> 0 | D34: =IFERROR(MAX(0,D29+375309)/375309,IF(D29<-375309,"DEFICITÁRIO","OK")) -> 0 | E34: =IFERROR(MAX(0,E29+375309)/375309,IF(E29<-375309,"DEFICITÁRIO","OK")) -> 0 | F34: =IFERROR(MAX(0,F29+375309)/375309,IF(F29<-375309,"DEFICITÁRIO","OK")) -> 0 | G34: =IFERROR(MAX(0,G29+375309)/375309,IF(G29<-375309,"DEFICITÁRIO","OK")) -> 0 | H34: =IFERROR(MAX(0,H29+375309)/375309,IF(H29<-375309,"DEFICITÁRIO","OK")) -> 0
B37: Cenários explicados:
B38: Status quo: PL como reportado pela SAF, sem ajustes. R$ (432) MM.
B39: C1 — Impairment 100% partes relacionadas: aplica provisão integral sobre R$ 564 MM (que o auditor diz ser necessária no parecer 2025).
B40: C2 — Adiciona ajuste FFU R$ 110 MM (parecer auditor #81) + PERSE contingente R$ 100 MM (estimativa para sensibilidade).
B41: C3 Lyon SAF ganha: SAF mantém crédito de R$ 564 MM integralmente; Lyon não é reconhecido. Cenário otimista para SAF.
B42: C3 Lyon — Acordo bilateral: ambos os lados escrevem 50% (impairment 50% partes relacionadas + 50% reconhecimento passivo Lyon). Cenário central.
B43: C3 Lyon ganha: SAF perde crédito (impairment 100%) e reconhece passivo Lyon integral (R$ 727 MM). Cenário pessimista.
B44: Resumo: o PL ajustado oscila entre R$ (550) MM (cenário otimista C3-SAF) e R$ (1.834) MM (cenário pessimista C3-Lyon).
